<?xml version="1.0"?>

<robot xmlns:xacro="http://www.ros.org/wiki/xacro" name="bumperbot">

  <xacro:arg name="is_ignition" default="true"/>  

  <!-- Base footprint -->
  <link name="base_footprint"/>

  <!-- Optional Gazebo plugins -->
  <xacro:include filename="bumperbot_gazebo.xacro"/>

   <!-- Include Ros2 Control -->
  <xacro:include filename="bumperbot_ros2_control.xacro"/>

  <!-- Base Link -->
  <link name="base_link">
    <inertial>
      <origin xyz="0 0 0.04" rpy="0 0 0"/>
      <mass value="0.82573504"/>
      <inertia ixx="0.022124416" ixy="-0.00012294101" ixz="0.00034938785"
               iyy="0.021193702" iyz="-0.000050120904" izz="0.020064271"/>
    </inertial>

    <visual>
      <origin xyz="0 0 0" rpy="0 0 0"/>
      <geometry>
        <mesh filename="package://bumperbot_description/meshes/base_link.STL"/>
      </geometry>
    </visual>

    <collision>
      <origin xyz="0 0 0" rpy="0 0 0"/>
      <geometry>
        <mesh filename="package://bumperbot_description/meshes/base_link.STL"/>
      </geometry>
    </collision>
  </link>

  <joint name="base_joint" type="fixed">
    <parent link="base_footprint"/>
    <child link="base_link"/>
    <origin xyz="0 0 0.033" rpy="0 0 0"/>
  </joint>

  <!-- Right Wheel -->
  <link name="wheel_right_link">
    <inertial>
      <origin xyz="0 0 0" rpy="0 0 0"/>
      <mass value="0.2"/>
      <inertia ixx="0.001" ixy="0" ixz="0"
               iyy="0.001" iyz="0" izz="0.001"/>
    </inertial>

    <visual>
      <origin xyz="0 0 0" rpy="1.57 0 0"/>
      <geometry>
        <mesh filename="package://bumperbot_description/meshes/wheel_right_link.STL"/>
      </geometry>
    </visual>

    <collision>
      <origin xyz="0 -0.015 0" rpy="1.57 0 0"/>
      <geometry>
        <sphere radius="0.033"/>
      </geometry>
    </collision>
  </link>

  <joint name="wheel_right_joint" type="continuous">
    <parent link="base_link"/>
    <child link="wheel_right_link"/>
    <origin xyz="0 -0.07 0" rpy="0 0 0"/>
    <axis xyz="0 1 0"/>
  </joint>

  <!-- Left Wheel -->
  <link name="wheel_left_link">
    <inertial>
      <origin xyz="0 0 0" rpy="0 0 0"/>
      <mass value="0.2"/>
      <inertia ixx="0.001" ixy="0" ixz="0"
               iyy="0.001" iyz="0" izz="0.001"/>
    </inertial>

    <visual>
      <origin xyz="0 0 0" rpy="-1.57 0 0"/>
      <geometry>
        <mesh filename="package://bumperbot_description/meshes/wheel_left_link.STL"/>
      </geometry>
    </visual>

    <collision>
      <origin xyz="0 0.015 0" rpy="1.57 0 0"/>
      <geometry>
        <sphere radius="0.033"/>
      </geometry>
    </collision>
  </link>

  <joint name="wheel_left_joint" type="continuous">
    <parent link="base_link"/>
    <child link="wheel_left_link"/>
    <origin xyz="0 0.07 0" rpy="0 0 0"/>
    <axis xyz="0 1 0"/>
  </joint>

  <!-- Front Caster -->
  <link name="caster_front_link">
    <inertial>
      <origin xyz="0 0 0" rpy="0 0 0"/>
      <mass value="0.05"/>
      <inertia ixx="0.0001" ixy="0" ixz="0"
               iyy="0.0001" iyz="0" izz="0.0001"/>
    </inertial>

    <visual>
      <origin xyz="0 0 0" rpy="0 0 0"/>
      <geometry>
        <mesh filename="package://bumperbot_description/meshes/caster_front_link.STL"/>
      </geometry>
    </visual>

    <collision>
      <geometry>
        <sphere radius="0.005"/>
      </geometry>
    </collision>
  </link>

  <joint name="caster_front_joint" type="fixed">
    <parent link="base_link"/>
    <child link="caster_front_link"/>
    <origin xyz="0.04755 0 -0.0275" rpy="0 0 0"/>
  </joint>

  <!-- Rear Caster -->
  <link name="caster_rear_link">
    <inertial>
      <origin xyz="0 0 0" rpy="0 0 0"/>
      <mass value="0.05"/>
      <inertia ixx="0.0001" ixy="0" ixz="0"
               iyy="0.0001" iyz="0" izz="0.0001"/>
    </inertial>

    <visual>
      <origin xyz="0 0 0" rpy="0 0 0"/>
      <geometry>
        <mesh filename="package://bumperbot_description/meshes/caster_rear_link.STL"/>
      </geometry>
    </visual>

    <collision>
      <geometry>
        <sphere radius="0.005"/>
      </geometry>
    </collision>
  </link>

  <joint name="caster_rear_joint" type="fixed">
    <parent link="base_link"/>
    <child link="caster_rear_link"/>
    <origin xyz="-0.04755 0 -0.0275" rpy="0 0 0"/>
  </joint>

</robot>